<?xml version="1.0"?>
<robot xmlns:controller="http://playerstage.sourceforge.net/gazebo/xmlschema/#controller"
       xmlns:interface="http://ros.org/wiki/xacro"
       xmlns:sensor="http://playerstage.sourceforge.net/gazebo/xmlschema/#sensor"
       xmlns:xacro="http://ros.org/wiki/xacro">

	<xacro:include filename="$(find tabletennisrobot_description)/urdf/TTbot.transmission.xacro" />
	<xacro:include filename="$(find tabletennisrobot_description)/urdf/TTbot.gazebo.xacro" />

	<!-- Kinematic model -->
  	<xacro:macro name="TTbot_robot" params="prefix">
		<!-- Links: -->	
		<link name="${prefix}base_link" >
			<inertial>
		    	<origin xyz="0 0 0" rpy="0 0 0" />
       			<mass value="93.462" />
       			<inertia ixx="13.838" ixy="0.0" ixz="0.0" iyy="95.310" iyz="0.0" izz="94.912" />
		    </inertial>
      		<visual>
		        <origin rpy="0 0 0" xyz="0 0 0" />
        		<geometry>
        			<mesh filename="package://tabletennisrobot_description/meshes/visual/base_link.dae" />
		        </geometry>
		    </visual>
      		<collision>
        		<origin rpy="0 0 0" xyz="0 0 0" />
        		<geometry>
          			<mesh filename="package://tabletennisrobot_description/meshes/visual/base_link.dae" />
		        </geometry>
 		    </collision>
    	</link>

		<link name="${prefix}slide_link" >
			<inertial>
		    	<origin xyz="0 0 0" rpy="0 0 0" />
       			<mass value="4.462" />
       			<inertia ixx="5.886E-02" ixy="0.0" ixz="0.0" iyy="1.426E-02" iyz="0.0" izz="6.193E-02" />
		    </inertial>
      		<visual>
		        <origin rpy="0 0 0" xyz="0 0 0" />
        		<geometry>
        			<mesh filename="package://tabletennisrobot_description/meshes/visual/slide_link.dae" />
		        </geometry>
		    </visual>
      		<collision>
        		<origin rpy="0 0 0" xyz="0 0 0" />
        		<geometry>
          			<mesh filename="package://tabletennisrobot_description/meshes/visual/slide_link.dae" />
		        </geometry>
 		    </collision>
    	</link>

		<link name="${prefix}joint_1_link" >
			<inertial>
		    	<origin xyz="${-0.125/2} 0 ${-0.125/2}" rpy="0 0 0" />
       			<mass value="1.610" />
       			<inertia ixx="9.545E-03" ixy="0.0" ixz="0.0" iyy="1.793E-03" iyz="0.0" izz="9.380E-03" />
		    </inertial>
      		<visual>
		        <origin xyz="${-0.125/2} 0 ${-0.125/2}" rpy="0 0 0" />
        		<geometry>
        			<mesh filename="package://tabletennisrobot_description/meshes/visual/joint_1_link.dae" />
		        </geometry>
		    </visual>
      		<collision>
        		<origin xyz="${-0.125/2} 0 ${-0.125/2}" rpy="0 0 0" />
        		<geometry>
          			<mesh filename="package://tabletennisrobot_description/meshes/visual/joint_1_link.dae" />
		        </geometry>
 		    </collision>
    	</link>

		<link name="${prefix}joint_2_link" >
			<inertial>
		    	<origin xyz="${-0.067/2} ${-0.015} ${-0.067/2}" rpy="0 0 0" />
       			<mass value="9.078E-01" />
       			<inertia ixx="9.568E-04" ixy="0.0" ixz="0.0" iyy="4.031E-02" iyz="0.0" izz="4.069E-02" />
		    </inertial>
      		<visual>
		        <origin xyz="${-0.067/2} ${-0.015} ${-0.067/2}" rpy="0 0 0" />
        		<geometry>
        			<mesh filename="package://tabletennisrobot_description/meshes/visual/joint_2_link.dae" />
		        </geometry>
		    </visual>
      		<collision>
        		<origin xyz="${-0.067/2} ${-0.015} ${-0.067/2}" rpy="0 0 0" />
        		<geometry>
          			<mesh filename="package://tabletennisrobot_description/meshes/visual/joint_2_link.dae" />
		        </geometry>
 		    </collision>
    	</link>

		<link name="${prefix}joint_3_link" >
			<inertial>
		    	<origin xyz="${-0.039/2} ${-0.023} ${-0.039/2}" rpy="0 0 0" />
       			<mass value="3.270E-01" />
       			<inertia ixx="1.203E-04" ixy="0.0" ixz="0.0" iyy="7.429E-3" iyz="0.0" izz="7.462E-3" />
		    </inertial>
      		<visual>
		        <origin xyz="${-0.039/2} ${-0.023} ${-0.039/2}" rpy="0 0 0" />
        		<geometry>
        			<mesh filename="package://tabletennisrobot_description/meshes/visual/joint_3_link.dae" />
		        </geometry>
		    </visual>
      		<collision>
        		<origin xyz="${-0.039/2} ${-0.023} ${-0.039/2}" rpy="0 0 0" />
        		<geometry>
          			<mesh filename="package://tabletennisrobot_description/meshes/visual/joint_3_link.dae" />
		        </geometry>
 		    </collision>
    	</link>

		<link name="${prefix}joint_4_link" >
			<inertial>
		    	<origin xyz="${-0.1+0.045/2} ${-0.01} ${-0.045/2}" rpy="0 ${0} 0" />
       			<mass value="1.331E-01" />
       			<inertia ixx="3.713E-05" ixy="0.0" ixz="0.0" iyy="2.703E-04" iyz="0.0" izz="2.622E-04" />
		    </inertial>
      		<visual>
		        <origin xyz="${-0.1+0.045/2} ${-0.01} ${-0.045/2}" rpy="0 ${0} 0" />
        		<geometry>
        			<mesh filename="package://tabletennisrobot_description/meshes/visual/joint_4_link.dae" />
		        </geometry>
		    </visual>
      		<collision>
        		<origin xyz="${-0.1+0.045/2} ${-0.01} ${-0.045/2}" rpy="0 ${0} 0" />
        		<geometry>
          			<mesh filename="package://tabletennisrobot_description/meshes/visual/joint_4_link.dae" />
		        </geometry>
 		    </collision>
    	</link>
    	
		<link name="${prefix}racket_link" >
			<inertial>
		    	<origin xyz="${0} ${0} ${0}" rpy="0 ${0} ${-pi/6}" />
       			<mass value="8.5E-02" />
       			<inertia ixx="3.713E-05" ixy="0.0" ixz="0.0" iyy="2.703E-04" iyz="0.0" izz="2.622E-04" />
		    </inertial>
      		<visual>
		        <origin xyz="${0} ${0} ${0}" rpy="0 ${0} ${-pi/6}" />
        		<geometry>
        			<mesh filename="package://tabletennisrobot_description/meshes/visual/racket3_1.dae" />
		        </geometry>
		    </visual>
      		<collision>
				<origin xyz="${0} ${0} ${0}" rpy="0 ${0} ${-pi/6}" />
        		<geometry>
          			<mesh filename="package://tabletennisrobot_description/meshes/visual/racket3_1.dae" />
		        </geometry>
 		    </collision>
    	</link>
    	
    	
    	
    	<!-- joints: -->
		<joint name="${prefix}joint_0" type="prismatic">
    		<origin xyz="0.0 0.4 0.621" rpy="${pi/2} 0 0" />
    		<parent link="${prefix}base_link" />
    		<child link = "${prefix}slide_link" />
    		<axis xyz="1 0 0" />
    		<limit effort="150" lower="0.2" upper="1.25" velocity="0.5" />
    		<dynamics damping="0.0" friction="0.0"/>
  		</joint>

		<joint name="${prefix}joint_1" type="revolute">
			<parent link="${prefix}slide_link"/>
        	<child link="${prefix}joint_1_link"/>

			<origin xyz="${0.147/2} ${0.225} ${0.15/2}" rpy="0 0 0" />
        	<limit effort="1000.0" lower="${-pi*3/4}" upper="${pi*3/4}" velocity="0.5"/>
        	<dynamics damping="0.0" friction="0.0"/>
        	<axis xyz="0 1 0"/>
    	</joint>

		<joint name="${prefix}joint_2" type="revolute">
			<parent link="${prefix}joint_1_link"/>
        	<child link="${prefix}joint_2_link"/>

			<origin xyz="${0.05} ${0.091} ${0}" rpy="0 0 ${pi/2}" />
        	<limit effort="1000.0" lower="${-pi*3/4}" upper="${pi*3/4}" velocity="0.5"/>
        	<dynamics damping="0.0" friction="0.0"/>
        	<axis xyz="0 1 0"/>
    	</joint>

		<joint name="${prefix}joint_3" type="revolute">
			<parent link="${prefix}joint_2_link"/>
        	<child link="${prefix}joint_3_link"/>

			<origin xyz="${0.253} ${0.082-0.015} ${0}" rpy="${pi} 0 0" />
        	<limit effort="1000.0" lower="${-pi*3/4}" upper="${pi*3/4}" velocity="0.5"/>
        	<dynamics damping="0.0" friction="0.0"/>
        	<axis xyz="0 1 0"/>
    	</joint>

		<joint name="${prefix}joint_4" type="revolute">
			<parent link="${prefix}joint_3_link"/>
        	<child link="${prefix}joint_4_link"/>

			<origin xyz="${0.216} ${0.04-0.023} ${0}" rpy="0 0 ${pi}" />
        	<limit effort="1000.0" lower="${-pi*3/4}" upper="${pi*3/4}" velocity="0.5"/>
        	<dynamics damping="0.0" friction="0.0"/>
        	<axis xyz="0 1 0"/>
    	</joint>

		<joint name="${prefix}joint_racket" type="fixed">
			<parent link="${prefix}joint_4_link"/>
        	<child link="${prefix}racket_link"/>
			<origin xyz="${-0.26-0.0325} ${0.015} ${0}" rpy="0 ${pi/2} ${0}" />
    	</joint>

		<!-- gazebo and transmission -->
		<xacro:TTbot_transmission prefix="${prefix}" />
    	<xacro:TTbot_gazebo prefix="${prefix}" />
	
	</xacro:macro>
</robot>
