<?xml version="1.0" encoding="utf-8"?>
<!-- =================================================================================== -->
<!-- |    This document was autogenerated by xacro from linear_slide_rail.urdf.xacro   | -->
<!-- |    EDITING THIS FILE BY HAND IS NOT RECOMMENDED                                 | -->
<!-- =================================================================================== -->
<robot name="linear_slide" xmlns:xacro="http://ros.org/wiki/xacro">
  <material name="gray">
    <color rgba="0.392156862745 0.392156862745 0.392156862745 1.0"/>
  </material>
  <material name="white">
    <color rgba="1.0 1.0 1.0 1.0"/>
  </material>
  <material name="blue">
    <color rgba="0.0 0.0 0.901960784314 1.0"/>
  </material>
  <link name="base_link">
    <visual>
      <geometry>
        <box size="0.4 1.6 0.6"/>
      </geometry>
      <material name="white"/>
    </visual>
    <collision>
      <geometry>
        <box size="0.4 1.6 0.6"/>
      </geometry>
    </collision>
    <inertial>
      <mass value="10"/>
      <inertia ixx="1.0" ixy="0.0" ixz="0.0" iyy="1.0" iyz="0.0" izz="1.0"/>
    </inertial>
  </link>
  <link name="r_slide_rail">
    <visual>
      <geometry>
        <box size="0.02 1.5 0.02"/>
      </geometry>
      <origin rpy="0 0 0" xyz="0 0 0.01"/>
      <material name="gray"/>
    </visual>
    <collision>
      <geometry>
        <box size="0.02 1.5 0.02"/>
      </geometry>
      <origin rpy="0 0 0" xyz="0 0 0.01"/>
    </collision>
    <inertial>
      <mass value="1"/>
      <inertia ixx="1.0" ixy="0.0" ixz="0.0" iyy="1.0" iyz="0.0" izz="1.0"/>
    </inertial>
  </link>
  <joint name="base_to_r_slide_rail" type="fixed">
    <parent link="base_link"/>
    <child link="r_slide_rail"/>
    <origin rpy="0 0 0" xyz="0.05 0 0.3"/>
  </joint>
  <link name="l_slide_rail">
    <visual>
      <geometry>
        <box size="0.02 1.5 0.02"/>
      </geometry>
      <origin rpy="0 0 0" xyz="0 0 0.01"/>
      <material name="gray"/>
    </visual>
    <collision>
      <geometry>
        <box size="0.02 1.5 0.02"/>
      </geometry>
      <origin rpy="0 0 0" xyz="0 0 0.01"/>
    </collision>
    <inertial>
      <mass value="1"/>
      <inertia ixx="1.0" ixy="0.0" ixz="0.0" iyy="1.0" iyz="0.0" izz="1.0"/>
    </inertial>
  </link>
  <joint name="base_to_l_slide_rail" type="fixed">
    <parent link="base_link"/>
    <child link="l_slide_rail"/>
    <origin rpy="0 0 0" xyz="-0.05 0 0.3"/>
  </joint>
  <joint name="j1_slide_block" type="prismatic">
    <parent link="r_slide_rail"/>
    <child link="slide_block_base"/>
    <limit effort="1000.0" lower="-0.7" upper="0.7" velocity="0.5"/>
    <origin xyz="-0.05 0 0.02"/>
    <dynamics damping="0.0" friction="0.0"/>
    <axis xyz="0 1 0"/>
  </joint>
  <link name="slide_block_base">
    <visual>
      <geometry>
        <box size="0.13 0.13 0.02"/>
      </geometry>
      <origin xyz="0 0 0.01"/>
      <material name="white"/>
    </visual>
    <collision>
      <geometry>
        <box size="0.13 0.13 0.02"/>
      </geometry>
      <origin xyz="0 0 0.01"/>
    </collision>
    <inertial>
      <mass value="0.05"/>
      <inertia ixx="1.0" ixy="0.0" ixz="0.0" iyy="1.0" iyz="0.0" izz="1.0"/>
    </inertial>
  </link>
  <transmission name="j1_slide_block_trans">
    <type>transmission_interface/SimpleTransmission</type>
    <actuator name="j1_slide_block_motor">
      <mechanicalReduction>1</mechanicalReduction>
    </actuator>
    <joint name="j1_slide_block">
      <hardwareInterface>PositionJointInterface</hardwareInterface>
    </joint>
  </transmission>
  <joint name="slide_block_to_j2block1" type="fixed">
    <parent link="slide_block_base"/>
    <child link="j2_block1"/>
    <origin xyz="0 0 0.02"/>
  </joint>
  <link name="j2_block1">
    <visual>
      <geometry>
        <box size="0.11 0.11 0.15"/>
      </geometry>
      <origin xyz="0 0 0.075"/>
      <material name="white"/>
    </visual>
    <collision>
      <geometry>
        <box size="0.11 0.11 0.15"/>
      </geometry>
      <origin xyz="0 0 0.075"/>
    </collision>
    <inertial>
      <mass value="0.05"/>
      <inertia ixx="1.0" ixy="0.0" ixz="0.0" iyy="1.0" iyz="0.0" izz="1.0"/>
    </inertial>
  </link>
  <joint name="j2_joint" type="revolute">
    <parent link="j2_block1"/>
    <child link="j2_block2"/>
    <limit effort="1000.0" lower="-2.356125" upper="2.356125" velocity="0.5"/>
    <origin xyz="0 0 0.15"/>
    <dynamics damping="0.0" friction="0.0"/>
    <axis xyz="0 0 1"/>
  </joint>
  <link name="j2_block2">
    <visual>
      <geometry>
        <cylinder length="0.07" radius="0.05"/>
      </geometry>
      <origin rpy="0 0 0" xyz="0 0 0"/>
      <material name="white"/>
    </visual>
    <collision>
      <geometry>
        <cylinder length="0.07" radius="0.05"/>
      </geometry>
      <origin rpy="0 0 0" xyz="0 0 0"/>
    </collision>
    <inertial>
      <mass value="0.05"/>
      <inertia ixx="1.0" ixy="0.0" ixz="0.0" iyy="1.0" iyz="0.0" izz="1.0"/>
    </inertial>
  </link>
  <joint name="j2block2_to_3" type="fixed">
    <parent link="j2_block2"/>
    <child link="j2_block3"/>
    <origin xyz="0 0 0.035"/>
  </joint>
  <link name="j2_block3">
    <visual>
      <geometry>
        <cylinder length="0.015" radius="0.065"/>
      </geometry>
      <origin rpy="0 0 0" xyz="0 0 0.0075"/>
      <material name="white"/>
    </visual>
    <collision>
      <geometry>
        <cylinder length="0.015" radius="0.065"/>
      </geometry>
      <origin rpy="0 0 0" xyz="0 0 0.0075"/>
    </collision>
    <inertial>
      <mass value="0.05"/>
      <inertia ixx="1.0" ixy="0.0" ixz="0.0" iyy="1.0" iyz="0.0" izz="1.0"/>
    </inertial>
  </link>
  <joint name="j2block3_to_4" type="fixed">
    <parent link="j2_block3"/>
    <child link="j2_block4"/>
    <origin xyz="0 0 0.015"/>
  </joint>
  <link name="j2_block4">
    <visual>
      <geometry>
        <box size="0.05 0.11 0.07"/>
      </geometry>
      <origin rpy="0 0 0" xyz="0 0 0.035"/>
      <material name="white"/>
    </visual>
    <collision>
      <geometry>
        <box size="0.05 0.11 0.07"/>
      </geometry>
      <origin rpy="0 0 0" xyz="0 0 0.035"/>
    </collision>
    <inertial>
      <mass value="0.05"/>
      <inertia ixx="1.0" ixy="0.0" ixz="0.0" iyy="1.0" iyz="0.0" izz="1.0"/>
    </inertial>
  </link>
  <joint name="j2block4_to_5" type="fixed">
    <parent link="j2_block4"/>
    <child link="j2_block5"/>
    <origin xyz="0 0 0.07"/>
  </joint>
  <link name="j2_block5">
    <visual>
      <geometry>
        <cylinder length="0.05" radius="0.055"/>
      </geometry>
      <origin rpy="0 1.57075 0" xyz="0 0 0"/>
      <material name="white"/>
    </visual>
    <collision>
      <geometry>
        <cylinder length="0.05" radius="0.055"/>
      </geometry>
      <origin rpy="0 1.57075 0" xyz="0 0 0"/>
    </collision>
    <inertial>
      <mass value="0.05"/>
      <inertia ixx="1.0" ixy="0.0" ixz="0.0" iyy="1.0" iyz="0.0" izz="1.0"/>
    </inertial>
  </link>
  <joint name="j3_joint" type="revolute">
    <parent link="j2_block5"/>
    <child link="j3_block1"/>
    <limit effort="1000.0" lower="-2.356125" upper="2.356125" velocity="0.5"/>
    <origin xyz="0 0 0"/>
    <dynamics damping="0.0" friction="0.0"/>
    <axis xyz="1 0 0"/>
  </joint>
  <link name="j3_block1">
    <visual>
      <geometry>
        <cylinder length="0.05" radius="0.02"/>
      </geometry>
      <origin rpy="0 1.57075 0" xyz="-0.025 0 0"/>
      <material name="white"/>
    </visual>
    <collision>
      <geometry>
        <cylinder length="0.05" radius="0.02"/>
      </geometry>
      <origin rpy="0 1.57075 0" xyz="-0.025 0 0"/>
    </collision>
    <inertial>
      <mass value="0.05"/>
      <inertia ixx="1.0" ixy="0.0" ixz="0.0" iyy="1.0" iyz="0.0" izz="1.0"/>
    </inertial>
  </link>
  <joint name="j3block1_to_2" type="fixed">
    <parent link="j3_block1"/>
    <child link="j3_block2"/>
    <origin xyz="-0.05 0 0"/>
  </joint>
  <link name="j3_block2">
    <visual>
      <geometry>
        <box size="0.02 0.05 0.3"/>
      </geometry>
      <origin rpy="0 0 0" xyz="0 0 0.1125"/>
      <material name="white"/>
    </visual>
    <collision>
      <geometry>
        <box size="0.02 0.05 0.3"/>
      </geometry>
      <origin rpy="0 0 0" xyz="0 0 0.1125"/>
    </collision>
    <inertial>
      <mass value="0.05"/>
      <inertia ixx="1.0" ixy="0.0" ixz="0.0" iyy="1.0" iyz="0.0" izz="1.0"/>
    </inertial>
  </link>
  <joint name="j4_joint" type="revolute">
    <parent link="j3_block2"/>
    <child link="j4_block1"/>
    <limit effort="1000.0" lower="-2.356125" upper="2.356125" velocity="0.5"/>
    <origin xyz="0 0 0.225"/>
    <dynamics damping="0.0" friction="0.0"/>
    <axis xyz="1 0 0"/>
  </joint>
  <link name="j4_block1">
    <visual>
      <geometry>
        <cylinder length="0.05" radius="0.02"/>
      </geometry>
      <origin rpy="0 1.57075 0" xyz="0.025 0 0"/>
      <material name="white"/>
    </visual>
    <collision>
      <geometry>
        <cylinder length="0.05" radius="0.02"/>
      </geometry>
      <origin rpy="0 1.57075 0" xyz="0.025 0 0"/>
    </collision>
    <inertial>
      <mass value="0.05"/>
      <inertia ixx="1.0" ixy="0.0" ixz="0.0" iyy="1.0" iyz="0.0" izz="1.0"/>
    </inertial>
  </link>
  <joint name="j4block1_to_2" type="fixed">
    <parent link="j4_block1"/>
    <child link="j4_block2"/>
    <origin xyz="0.05 0 0"/>
  </joint>
  <link name="j4_block2">
    <visual>
      <geometry>
        <box size="0.02 0.05 0.2"/>
      </geometry>
      <origin rpy="0 0 0" xyz="0 0 0.075"/>
      <material name="white"/>
    </visual>
    <collision>
      <geometry>
        <box size="0.02 0.05 0.2"/>
      </geometry>
      <origin rpy="0 0 0" xyz="0 0 0.075"/>
    </collision>
    <inertial>
      <mass value="0.05"/>
      <inertia ixx="1.0" ixy="0.0" ixz="0.0" iyy="1.0" iyz="0.0" izz="1.0"/>
    </inertial>
  </link>
  <joint name="j5_joint" type="revolute">
    <parent link="j4_block2"/>
    <child link="j5_block1"/>
    <limit effort="1000.0" lower="-2.356125" upper="2.356125" velocity="0.5"/>
    <origin xyz="0 0 0.15"/>
    <dynamics damping="0.0" friction="0.0"/>
    <axis xyz="1 0 0"/>
  </joint>
  <link name="j5_block1">
    <visual>
      <geometry>
        <cylinder length="0.05" radius="0.02"/>
      </geometry>
      <origin rpy="0 1.57075 0" xyz="-0.025 0 0"/>
      <material name="white"/>
    </visual>
    <collision>
      <geometry>
        <cylinder length="0.05" radius="0.02"/>
      </geometry>
      <origin rpy="0 1.57075 0" xyz="-0.025 0 0"/>
    </collision>
    <inertial>
      <mass value="0.05"/>
      <inertia ixx="1.0" ixy="0.0" ixz="0.0" iyy="1.0" iyz="0.0" izz="1.0"/>
    </inertial>
  </link>
  <joint name="j5block1_to_2" type="fixed">
    <parent link="j5_block1"/>
    <child link="j5_block2"/>
    <origin xyz="-0.05 0 0"/>
  </joint>
  <link name="j5_block2">
    <visual>
      <geometry>
        <box size="0.02 0.05 0.15"/>
      </geometry>
      <origin rpy="0 0 0" xyz="0 0 0.05625"/>
      <material name="white"/>
    </visual>
    <collision>
      <geometry>
        <box size="0.02 0.05 0.15"/>
      </geometry>
      <origin rpy="0 0 0" xyz="0 0 0.05625"/>
    </collision>
    <inertial>
      <mass value="0.05"/>
      <inertia ixx="1.0" ixy="0.0" ixz="0.0" iyy="1.0" iyz="0.0" izz="1.0"/>
    </inertial>
  </link>
</robot>
